Workbook

Sheet Voorstel
B1: standaard NLCS statussen | C1: voorstel NLCS netbeheer substatusssen | D1: NLCS netbeheer bewerkingen
B2: B | C2: In Bedrijf
B3: N | C3: Nieuw | F3: positie substatus (nu 01-99) uitbreiden met mogelijkheid afkorting in 2 letters
B4: R | F4: gebruik van positie bewerking blijven gebruiken voor bewerking. Terminologie vastleggen voor netbeheer
B5: T
B6: V | C6: Verwijderd
B8: teken BEDRIJFSTOESTAND | C8: (
C9: )
C11: =$C$8&D11&$C$9 -> (VERLATEN) | D11: VERLATEN
C12: =$C$8&D12&$C$9 -> (RESERVE) | D12: RESERVE
C13: (IN BEDRIJF)
D14: IN BEDRIJF NEMEN
D15: RESERVE STELLEN
D16: VERLATEN STELLEN
D17: RELINEN
D18: OPVULLEN
D19: VERPLAATSEN
D20: TE VERWIJDEREN | F20: voorbeeld NLCS object leiding | G20: OI-KL-GAS_LD_DISTRIBUTIE_100 MBAR_NGIJ_118
F21: voorbeeld NLCS object kabel | G21: OI-KL-ET_MS_DISTRIBUTIE_6 kV_3x95Cu
F22: voorbeeld elementcode | G22: -G
G23: -
D24: Startsituatie | H24: plantekening | O24: revisietekening
B25: Startsituatie | C25: Eindsituatie | D25: NLCS status | E25: NLCS netbeheer Bedrijfstoestand | F25: voorbeeld NLCS laagnaam | H25: NLCS status | J25: NLCS netbeheer Bedrijfstoestand | L25: Bewerking | M25: voorbeeld NLCS laagnaam | O25: NLCS status | Q25: NLCS netbeheer Bedrijfstoestand | S25: Bewerking | T25: voorbeeld NLCS laagnaam
B26: Bestaand, in Bedrijf | C26: Bestaand, in Bedrijf | D26: B | E26: =C13 -> (IN BEDRIJF) | F26: =D26&$G$23&$G$21&"-"&E26&$G$22 -> B-OI-KL-ET_MS_DISTRIBUTIE_6 kV_3x95Cu-(IN BEDRIJF)-G | H26: B | I26: =IF(AND(L26="",J26=""),"","-") -> - | J26: =C13 -> (IN BEDRIJF) | K26: =IF(OR(L26="",J26=""),"","_") | M26: =H26&$G$23&$G$21&I26&J26&K26&L26&$G$22 -> B-OI-KL-ET_MS_DISTRIBUTIE_6 kV_3x95Cu-(IN BEDRIJF)-G | O26: B | P26: =IF(AND(S26="",Q26=""),"","-") -> - | Q26: =C13 -> (IN BEDRIJF) | R26: =IF(OR(S26="",Q26=""),"","_") | T26: =O26&$G$23&$G$21&P26&Q26&R26&S26&$G$22 -> B-OI-KL-ET_MS_DISTRIBUTIE_6 kV_3x95Cu-(IN BEDRIJF)-G
B27: Bestaand, in Bedrijf | C27: Bestaand, verlaten | D27: B | E27: =C13 -> (IN BEDRIJF) | F27: =D27&$G$23&$G$21&"-"&E27&$G$22 -> B-OI-KL-ET_MS_DISTRIBUTIE_6 kV_3x95Cu-(IN BEDRIJF)-G | H27: B | I27: =IF(AND(L27="",J27=""),"","-") -> - | J27: =C13 -> (IN BEDRIJF) | K27: =IF(OR(L27="",J27=""),"","_") -> _ | L27: =D16 -> VERLATEN STELLEN | M27: =H27&$G$23&$G$21&I27&J27&K27&L27&$G$22 -> B-OI-KL-ET_MS_DISTRIBUTIE_6 kV_3x95Cu-(IN BEDRIJF)_VERLATEN STELLEN-G | O27: R | P27: =IF(AND(S27="",Q27=""),"","-") -> - | Q27: =C11 -> (VERLATEN) | R27: =IF(OR(S27="",Q27=""),"","_") | T27: =O27&$G$23&$G$21&P27&Q27&R27&S27&$G$22 -> R-OI-KL-ET_MS_DISTRIBUTIE_6 kV_3x95Cu-(VERLATEN)-G
B28: Bestaand, in Bedrijf | C28: Bestaand, reserve | D28: B | E28: =C13 -> (IN BEDRIJF) | F28: =D28&$G$23&$G$21&"-"&E28&$G$22 -> B-OI-KL-ET_MS_DISTRIBUTIE_6 kV_3x95Cu-(IN BEDRIJF)-G | H28: B | I28: =IF(AND(L28="",J28=""),"","-") -> - | J28: =C13 -> (IN BEDRIJF) | K28: =IF(OR(L28="",J28=""),"","_") -> _ | L28: =D15 -> RESERVE STELLEN | M28: =H28&$G$23&$G$21&I28&J28&K28&L28&$G$22 -> B-OI-KL-ET_MS_DISTRIBUTIE_6 kV_3x95Cu-(IN BEDRIJF)_RESERVE STELLEN-G | O28: R | P28: =IF(AND(S28="",Q28=""),"","-") -> - | Q28: =C12 -> (RESERVE) | R28: =IF(OR(S28="",Q28=""),"","_") | T28: =O28&$G$23&$G$21&P28&Q28&R28&S28&$G$22 -> R-OI-KL-ET_MS_DISTRIBUTIE_6 kV_3x95Cu-(RESERVE)-G
B29: Bestaand, in Bedrijf | C29: Verwijderd | D29: B | E29: =C13 -> (IN BEDRIJF) | F29: =D29&$G$23&$G$21&"-"&E29&$G$22 -> B-OI-KL-ET_MS_DISTRIBUTIE_6 kV_3x95Cu-(IN BEDRIJF)-G | H29: B | I29: =IF(AND(L29="",J29=""),"","-") -> - | J29: =C13 -> (IN BEDRIJF) | K29: =IF(OR(L29="",J29=""),"","_") -> _ | L29: =D20 -> TE VERWIJDEREN | M29: =H29&$G$23&$G$21&I29&J29&K29&L29&$G$22 -> B-OI-KL-ET_MS_DISTRIBUTIE_6 kV_3x95Cu-(IN BEDRIJF)_TE VERWIJDEREN-G | O29: V | P29: =IF(AND(S29="",Q29=""),"","-") | R29: =IF(OR(S29="",Q29=""),"","_") | T29: =O29&$G$23&$G$21&P29&Q29&R29&S29&$G$22 -> V-OI-KL-ET_MS_DISTRIBUTIE_6 kV_3x95Cu-G
B30: Bestaand, in Bedrijf | C30: Bestaand, Verplaatsen | D30: B | E30: =C13 -> (IN BEDRIJF) | F30: =D30&$G$23&$G$21&"-"&E30&$G$22 -> B-OI-KL-ET_MS_DISTRIBUTIE_6 kV_3x95Cu-(IN BEDRIJF)-G | H30: B | I30: =IF(AND(L30="",J30=""),"","-") | K30: =IF(OR(L30="",J30=""),"","_") | M30: =H30&$G$23&$G$21&I30&J30&K30&L30&$G$22 -> B-OI-KL-ET_MS_DISTRIBUTIE_6 kV_3x95Cu-G | O30: B | P30: =IF(AND(S30="",Q30=""),"","-") | R30: =IF(OR(S30="",Q30=""),"","_") | T30: =O30&$G$23&$G$21&P30&Q30&R30&S30&$G$22 -> B-OI-KL-ET_MS_DISTRIBUTIE_6 kV_3x95Cu-G
H31: R | I31: =IF(AND(L31="",J31=""),"","-") | K31: =IF(OR(L31="",J31=""),"","_") | M31: =H31&$G$23&$G$21&I31&J31&K31&L31&$G$22 -> R-OI-KL-ET_MS_DISTRIBUTIE_6 kV_3x95Cu-G | O31: R | P31: =IF(AND(S31="",Q31=""),"","-") -> - | Q31: =C13 -> (IN BEDRIJF) | R31: =IF(OR(S31="",Q31=""),"","_") | T31: =O31&$G$23&$G$21&P31&Q31&R31&S31&$G$22 -> R-OI-KL-ET_MS_DISTRIBUTIE_6 kV_3x95Cu-(IN BEDRIJF)-G
H32: B | L32: VERPLAATSEN | M32: B-OI-KL-ET-VERPLAATSEN-G
H33: N | L33: VERPLAATSEN | M33: N-OI-KL-ET-VERPLAATSEN-G
B34: Bestaand, verlaten | C34: Verwijderd | D34: B | E34: =C11 -> (VERLATEN) | F34: =D34&$G$23&$G$21&"-"&E34&$G$22 -> B-OI-KL-ET_MS_DISTRIBUTIE_6 kV_3x95Cu-(VERLATEN)-G | H34: B | I34: =IF(AND(L34="",J34=""),"","-") -> - | J34: =E34 -> (VERLATEN) | K34: =IF(OR(L34="",J34=""),"","_") -> _ | L34: =D20 -> TE VERWIJDEREN | M34: =H34&$G$23&$G$21&I34&J34&K34&L34&$G$22 -> B-OI-KL-ET_MS_DISTRIBUTIE_6 kV_3x95Cu-(VERLATEN)_TE VERWIJDEREN-G | O34: V | P34: =IF(AND(S34="",Q34=""),"","-") | R34: =IF(OR(S34="",Q34=""),"","_") | T34: =O34&$G$23&$G$21&P34&Q34&R34&S34&$G$22 -> V-OI-KL-ET_MS_DISTRIBUTIE_6 kV_3x95Cu-G
B35: Bestaand, reserve | C35: Verwijderd | D35: B | E35: =C12 -> (RESERVE) | F35: =D35&$G$23&$G$21&"-"&E35&$G$22 -> B-OI-KL-ET_MS_DISTRIBUTIE_6 kV_3x95Cu-(RESERVE)-G | H35: B | I35: =IF(AND(L35="",J35=""),"","-") -> - | J35: =C12 -> (RESERVE) | K35: =IF(OR(L35="",J35=""),"","_") -> _ | L35: =D20 -> TE VERWIJDEREN | M35: =H35&$G$23&$G$21&I35&J35&K35&L35&$G$22 -> B-OI-KL-ET_MS_DISTRIBUTIE_6 kV_3x95Cu-(RESERVE)_TE VERWIJDEREN-G | O35: V | P35: =IF(AND(S35="",Q35=""),"","-") | R35: =IF(OR(S35="",Q35=""),"","_") | T35: =O35&$G$23&$G$21&P35&Q35&R35&S35&$G$22 -> V-OI-KL-ET_MS_DISTRIBUTIE_6 kV_3x95Cu-G
B36: Bestaand, reserve | C36: Bestaand, in Bedrijf | D36: B | E36: =C12 -> (RESERVE) | F36: =D36&$G$23&$G$21&"-"&E36&$G$22 -> B-OI-KL-ET_MS_DISTRIBUTIE_6 kV_3x95Cu-(RESERVE)-G | H36: B | I36: =IF(AND(L36="",J36=""),"","-") -> - | J36: =C12 -> (RESERVE) | K36: =IF(OR(L36="",J36=""),"","_") -> _ | L36: =D14 -> IN BEDRIJF NEMEN | M36: =H36&$G$23&$G$21&I36&J36&K36&L36&$G$22 -> B-OI-KL-ET_MS_DISTRIBUTIE_6 kV_3x95Cu-(RESERVE)_IN BEDRIJF NEMEN-G | O36: R | P36: =IF(AND(S36="",Q36=""),"","-") | R36: =IF(OR(S36="",Q36=""),"","_") | T36: =O36&$G$23&$G$21&P36&Q36&R36&S36&$G$22 -> R-OI-KL-ET_MS_DISTRIBUTIE_6 kV_3x95Cu-G
B37: Bestaand, reserve | C37: Bestaand, verlaten | D37: B | E37: =C12 -> (RESERVE) | F37: =D37&$G$23&$G$21&"-"&E37&$G$22 -> B-OI-KL-ET_MS_DISTRIBUTIE_6 kV_3x95Cu-(RESERVE)-G | H37: B | I37: =IF(AND(L37="",J37=""),"","-") -> - | J37: =C12 -> (RESERVE) | K37: =IF(OR(L37="",J37=""),"","_") -> _ | L37: =D16 -> VERLATEN STELLEN | M37: =H37&$G$23&$G$21&I37&J37&K37&L37&$G$22 -> B-OI-KL-ET_MS_DISTRIBUTIE_6 kV_3x95Cu-(RESERVE)_VERLATEN STELLEN-G | O37: R | P37: =IF(AND(S37="",Q37=""),"","-") -> - | Q37: =C11 -> (VERLATEN) | R37: =IF(OR(S37="",Q37=""),"","_") | T37: =O37&$G$23&$G$21&P37&Q37&R37&S37&$G$22 -> R-OI-KL-ET_MS_DISTRIBUTIE_6 kV_3x95Cu-(VERLATEN)-G
C38: Nieuw, in Bedrijf | H38: N | I38: =IF(AND(L38="",J38=""),"","-") -> - | K38: =IF(OR(L38="",J38=""),"","_") | L38: =D14 -> IN BEDRIJF NEMEN | M38: =H38&$G$23&$G$21&I38&J38&K38&L38&$G$22 -> N-OI-KL-ET_MS_DISTRIBUTIE_6 kV_3x95Cu-IN BEDRIJF NEMEN-G | O38: N | P38: =IF(AND(S38="",Q38=""),"","-") -> - | Q38: =C13 -> (IN BEDRIJF) | R38: =IF(OR(S38="",Q38=""),"","_") | T38: =O38&$G$23&$G$21&P38&Q38&R38&S38&$G$22 -> N-OI-KL-ET_MS_DISTRIBUTIE_6 kV_3x95Cu-(IN BEDRIJF)-G
C39: Nieuw, Verlaten
C40: Nieuw, Nieuw Reserve | H40: N | I40: =IF(AND(L40="",J40=""),"","-") -> - | K40: =IF(OR(L40="",J40=""),"","_") | L40: =D15 -> RESERVE STELLEN | M40: =H40&$G$23&$G$21&I40&J40&K40&L40&$G$22 -> N-OI-KL-ET_MS_DISTRIBUTIE_6 kV_3x95Cu-RESERVE STELLEN-G | O40: N | P40: =IF(AND(S40="",Q40=""),"","-") -> - | Q40: =C12 -> (RESERVE) | R40: =IF(OR(S40="",Q40=""),"","_") | T40: =O40&$G$23&$G$21&P40&Q40&R40&S40&$G$22 -> N-OI-KL-ET_MS_DISTRIBUTIE_6 kV_3x95Cu-(RESERVE)-G
B42: Bestaand, in Bedrijf | C42: Bestaand, opgevuld | D42: B | F42: =D42&E42&$G$23&$G$20&$G$22 -> B-OI-KL-GAS_LD_DISTRIBUTIE_100 MBAR_NGIJ_118-G | H42: B | L42: OPVULLEN | M42: =H42&$G$23&G20&IF(J42<>"",IF(L42<>"","-"&J42&"_"&L42,""),IF(L42<>"","-"&L42,""))&$G$22 -> B-OI-KL-GAS_LD_DISTRIBUTIE_100 MBAR_NGIJ_118-OPVULLEN-G | O42: R | Q42: =C11 -> (VERLATEN) | T42: =O42&$G$23&G20&IF(Q42<>"","_"&Q42,"")&IF(S42<>"","-"&S42,"")&$G$22 -> R-OI-KL-GAS_LD_DISTRIBUTIE_100 MBAR_NGIJ_118_(VERLATEN)-G
B43: Bestaand, in Bedrijf | C43: Bestaand, gerelined | D43: B | F43: =D43&E43&$G$23&$G$20&$G$22 -> B-OI-KL-GAS_LD_DISTRIBUTIE_100 MBAR_NGIJ_118-G | H43: B | L43: RELINEN | M43: =H43&$G$23&G20&IF(J43<>"",IF(L43<>"","-"&J43&"_"&L43,""),IF(L43<>"","-"&L43,""))&$G$22 -> B-OI-KL-GAS_LD_DISTRIBUTIE_100 MBAR_NGIJ_118-RELINEN-G | O43: R | T43: R-OI-KL-GAS_LD_DISTRIBUTIE_100 MBAR_KOUSIJZER_118-G
...

Sheet termen status-bewerkingen
A1: Stedin Terminologie | B1: Liander Terminologie | C1: Enexis | D1: Brabant Water | E1: Vitens | F1: Statusbenaming informatiemodel | G1: NLCS Status | H1: Bewerking | I1: Opmerking
A2: VOLSCHUIMEN | H2: OPVULLEN
A3: DEMPEN | H3: OPVULLEN | K3: Onderscheid maken in | L3: Operatie status,Acties = Ontwerp / TODO,RegistratieStatus
A4: NIEUW TE LEGGEN | B4: Nieuw te leggen/plaatsen | C4: gepland | E4: NIEUW TE LEGGEN | F4: Nieuw | G4: N
A5: ROOIEN | B5: ?? Uit te nemen | C5: te verwijderen | E5: TE ROOIEN | G5: V
B6: ?? Te relinen | E6: RELINEN | H6: RELINEN
A7: RIJZEN | H7: VERPLAATSEN
A8: VERPLAATSEN (voorbeeld OV) & OMKLAPPEN | B8: Om te leggen & Na te verleggen | H8: VERPLAATSEN
A9: DÄMMEREN | C9: buiten bedrijf gedemmerd | E9: TE DÄMMEREN | H9: OPVULLEN
A10: OPNEMEN | H10: VERPLAATSEN
A11: BUITEN BEDRIJF & BB | B11: Buitenbedrijf te stellen | C11: buiten bedrijf schroot | E11: BUITEN GEBRUIK TE STELLEN | G11: ?BB | H11: VERLATEN
A12: IN BEDRIJF & IB | B12: In bedrijf te stellen | C12: in bedrijf te nemen | G12: ?IB of enkel ? | H12: IG NEMEN
C13: buiten bedrijf te stellen
E14: VERVALLEN LEIDING
B15: Te vervangen | E15: TE VERVANGEN LEIDING | I15: Kiezen voor Verwijderen en Nieuw als workflow
B16: ?? Te verlaten | I16: gelijk aan buiten bedrijf stellen
A17: HERBRUIKBAAR | B17: reserve | C17: buiten bedrijf
D18: bestaande leiding wordt mantelbuis
B19: Uitgenomen | D19: Verwijderd
A20: In Bedrijf | B20: In Bedrijf | C20: in bedrijf | D20: In Bedrijf
A22: STEDIN EO | G22: Beschrijving AM | H22: definitie | I22: NLCS Status | J22: NLCS Bewerking | K22: Voorbeeld NLCS Laag - Plantekening voor Export EO
A23: Aangelegd | G23: Aangelegd maar nog niet in gebruik. Komt voor bij deelopleveringen van o.a. kabelverbindingen. | H23: nieuw aangelegde asset buiten bedrijf | I23: RVL | K23: =IF(J23="",I23&"-"&Voorstel!$G$21&'termen status-bewerkingen'!J23&Voorstel!$G$22,I23&"-"&Voorstel!$G$21&"-"&'termen status-bewerkingen'!J23&Voorstel!$G$22) -> RVL-OI-KL-ET_MS_DISTRIBUTIE_6 kV_3x95Cu-G
A24: Geplande aanleg | G24: Ontwerp nieuwe aanleg | H24: nieuw fysieke asset | I24: N | K24: =IF(J24="",I24&"-"&Voorstel!$G$21&'termen status-bewerkingen'!J24&Voorstel!$G$22,I24&"-"&Voorstel!$G$21&"-"&'termen status-bewerkingen'!J24&Voorstel!$G$22) -> N-OI-KL-ET_MS_DISTRIBUTIE_6 kV_3x95Cu-G
A25: Geplande verlating | G25: Ontwerp bestaande te gaan verlaten | H25: bestaande asset buiten bedrijf te stellen | I25: B | J25: VERLATEN | K25: =IF(J25="",I25&"-"&Voorstel!$G$21&'termen status-bewerkingen'!J25&Voorstel!$G$22,I25&"-"&Voorstel!$G$21&"-"&'termen status-bewerkingen'!J25&Voorstel!$G$22) -> B-OI-KL-ET_MS_DISTRIBUTIE_6 kV_3x95Cu-VERLATEN-G
A26: Geplande verplaatsing | G26: Ontwerp om o.a. bestaande te verplaatsen of op te halen (diepte correctie) | H26: bestaande asset naar nieuwe locatie verplaatsen | I26: B | J26: VERPLAATSEN | K26: =IF(J26="",I26&"-"&Voorstel!$G$21&'termen status-bewerkingen'!J26&Voorstel!$G$22,I26&"-"&Voorstel!$G$21&"-"&'termen status-bewerkingen'!J26&Voorstel!$G$22) -> B-OI-KL-ET_MS_DISTRIBUTIE_6 kV_3x95Cu-VERPLAATSEN-G
A27: Geplande vervanging | G27: Ontwerp om asset te gaan verwijderen en nieuwe asset te plaatsen | H27: bestaande asset in gebruik, opnemen asset en nieuw asset plaatsen | I27: B | J27: VERVANGEN | K27: =IF(J27="",I27&"-"&Voorstel!$G$21&'termen status-bewerkingen'!J27&Voorstel!$G$22,I27&"-"&Voorstel!$G$21&"-"&'termen status-bewerkingen'!J27&Voorstel!$G$22) -> B-OI-KL-ET_MS_DISTRIBUTIE_6 kV_3x95Cu-VERVANGEN-G
A28: Geplande verwijdering | G28: Ontwerp om te gaat verwijderen | H28: bestaande asset in gebruik, toekomstige verwijdering | I28: V | J28: VERWIJDEREN | K28: =IF(J28="",I28&"-"&Voorstel!$G$21&'termen status-bewerkingen'!J28&Voorstel!$G$22,I28&"-"&Voorstel!$G$21&"-"&'termen status-bewerkingen'!J28&Voorstel!$G$22) -> V-OI-KL-ET_MS_DISTRIBUTIE_6 kV_3x95Cu-VERWIJDEREN-G
A29: In gebruik | G29: Aangelegd en in gebruik genomen | H29: bestaande asset in gebruik | I29: B | K29: =IF(J29="",I29&"-"&Voorstel!$G$21&'termen status-bewerkingen'!J29&Voorstel!$G$22,I29&"-"&Voorstel!$G$21&"-"&'termen status-bewerkingen'!J29&Voorstel!$G$22) -> B-OI-KL-ET_MS_DISTRIBUTIE_6 kV_3x95Cu-G
A30: Verlaten | G30: Verlaten en dus niet verwijderd | H30: bestaande asset, fysiek aanwezig, buiten gebruik | I30: BVL | K30: =IF(J30="",I30&"-"&Voorstel!$G$21&'termen status-bewerkingen'!J30&Voorstel!$G$22,I30&"-"&Voorstel!$G$21&"-"&'termen status-bewerkingen'!J30&Voorstel!$G$22) -> BVL-OI-KL-ET_MS_DISTRIBUTIE_6 kV_3x95Cu-G
A31: Verwijderd | G31: Fysiek verwijderd / geen eigendom meer van Stedin | H31: asset fysiek niet aanwezig, aanduiding oorspronkelijke ligging | I31: VVL | K31: =IF(J31="",I31&"-"&Voorstel!$G$21&'termen status-bewerkingen'!J31&Voorstel!$G$22,I31&"-"&Voorstel!$G$21&"-"&'termen status-bewerkingen'!J31&Voorstel!$G$22) -> VVL-OI-KL-ET_MS_DISTRIBUTIE_6 kV_3x95Cu-G

Sheet Statusbenamingen
A1: NLCS Status | B1: NLCS Bedrijfstoestand | C1: NLCS informatiemodel status | D1: Definitie
A2: B | B2: IN BEDRIJF | C2: BESTAAND | D2: Bestaande asset: deze asset is reeds aanwezig voordat het project start
B3: RESERVE | C3: BESTAAND | D3: Bestaande asset, reserve: de asset is reeds aanwezig voorafgaand aan het project, is niet in gebruik, maar kan wel in gebruik worden genomen
B4: VERLATEN | C4: BESTAAND | D4: Bestaande asset, Verlaten: de asset is reeds aanwezig voorafgaand aan het project, is niet in gebruik en kan niet meer in gebruik worden genomen
A5: N | B5: IN BEDRIJF | C5: NIEUW | D5: Nieuwe asset: de asset wordt gedurende het project toegevoegd/geïnstalleerd
B6: RESERVE | C6: NIEUW | D6: Nieuwe asset: de asset wordt gedurende het project toegevoegd/geïnstalleerd, maar wordt nog niet in gebruik genomen.
A7: R | B7: IN BEDRIJF | C7: REVISIE | D7: Revisie: deze asset is gedurende het project aangepast (alfanumeriek en/of geografisch)
A8: R | B8: VERLATEN | C8: REVISIE | D8: Revisie: deze asset is gedurende het project aangepast (alfanumeriek en/of geografisch) en deze asset is na het project niet meer in gebruik en kan ook niet meer in gebruik worden genomen.
A9: R | B9: RESERVE | C9: REVISIE | D9: Revisie: deze asset is gedurende het project aangepast (alfanumeriek en/of geografisch) en deze asset is na het project (nog) niet in gebruik, maar kan wel in gebruik worden genomen.
A10: T | B10: IN BEDRIJF | C10: TIJDELIJK | D10: Deze status komt alleen voor in een Ontwerptekening en een deelrevisie, niet in een As-built eindrevisietekening en wordt gebruikt voor assets of objecten die alleen bestaan en in bedrijf zijn gedurende het project
A11: T | B11: RESERVE | C11: TIJDELIJK | D11: Deze status komt alleen voor in een Ontwerptekening en een deelrevisie, niet in een As-built eindrevisietekening en wordt gebruikt voor assets of objecten die alleen bestaan gedurende het project. De bedrijfstoestand RESERVE is van toepassing wanneer de asset niet in bedrijf is maar wel in bedrijf kan worden genomen.
A12: V | C12: VERWIJDERD | D12: Verwijderd (soms ook aangeduid met Vervallen): de asset is tijdens het project fysiek verwijderd, bijvoorbeeld uit de grond gehaald.
C14: Bewerking | D14: Definitie
C15: VERLATEN STELLEN | D15: De asset wordt tijdens het project verlaten, hetgeen betekent dat de asset daarna nooit meer kan worden gebruikt. De asset blijft fysiek op locatie aanwezig. Deze Bewerking wordt NIET gekozen indien een leiding wordt opgevuld, want daarvoor is een meer specifieke Bewerking "Opvullen" beschikbaar
C16: IN BEDRIJF NEMEN | D16: De asset was al aanwezig voorafgaand aan het project en wordt gedurende het project in gebruik genomen, bijvoorbeeld onder druk gezet of onder spanning gebracht.
C17: RESERVE STELLEN | D17: De asset wordt tijdens het project: 1. Indien bestaand object: uit gebruik genomen, maar kan in de toekomst weer in gebruik worden genomen 2. Indien Nieuw object: wel geplaatst, maar (nog) niet in gebruik genomen. Dat kan later alsnog worden gedaan.
C18: RELINEN | D18: Alleen van toepassing op leidingen, niet op kabels: er wordt een techniek toegepast om een oude leiding langer te kunnen gebruiken door deze van een nieuwe binnenwand te voorzien.
C19: OPVULLEN | D19: Alleen van toepassing op leidingen, niet op kabels: dit is een manier van verlaten (Buiten Bedrijf stellen): de leiding wordt opgevuld (volschuimen, dämmeren etc) en wordt daarmee voorgoed buiten bedrijf gesteld.
C20: VERPLAATSEN | D20: Een bestaande asset moet naar een andere locatie worden verplaatst (omgelegd, omgeklapt, rijzen etc), maar behoudt zijn asset eigenschappen.
C21: TE VERWIJDEREN | D21: Een bestaande asset uit de grond worden verwijderd en bestaat dus niet meer na afloop van het project.
